2019-05-12 18:17:52,484,484 INF botan.main.main(18) run botan 
2019-05-12 18:17:52,496,496 INF botan.serve.main(16) run serve subcommand 
2019-05-12 18:17:54,519,519 WAR aiogram._skip_updates(342) Updates are skipped successfully. 
2019-05-12 18:19:37,530,530 DEB urllib3.connectionpool._new_conn(813) Starting new HTTPS connection (1): translate.yandex.net:443 
2019-05-12 18:19:38,459,459 DEB urllib3.connectionpool._make_request(393) https://translate.yandex.net:443 "POST /api/v1.5/tr.json/translate HTTP/1.1" 200 41 
2019-05-12 18:19:38,475,475 DEB urllib3.connectionpool._new_conn(813) Starting new HTTPS connection (1): translate.yandex.net:443 
2019-05-12 18:19:39,262,262 DEB urllib3.connectionpool._make_request(393) https://translate.yandex.net:443 "POST /api/v1.5/tr.json/translate HTTP/1.1" 200 79 
2019-05-12 18:19:52,753,753 DEB urllib3.connectionpool._new_conn(813) Starting new HTTPS connection (1): translate.yandex.net:443 
2019-05-12 18:19:53,672,672 DEB urllib3.connectionpool._make_request(393) https://translate.yandex.net:443 "POST /api/v1.5/tr.json/translate HTTP/1.1" 200 42 
2019-05-12 18:19:53,696,696 DEB urllib3.connectionpool._new_conn(813) Starting new HTTPS connection (1): translate.yandex.net:443 
2019-05-12 18:19:54,362,362 DEB urllib3.connectionpool._make_request(393) https://translate.yandex.net:443 "POST /api/v1.5/tr.json/translate HTTP/1.1" 200 44 
2019-05-12 18:20:26,863,863 DEB urllib3.connectionpool._new_conn(813) Starting new HTTPS connection (1): translate.yandex.net:443 
2019-05-12 18:20:27,406,406 DEB urllib3.connectionpool._make_request(393) https://translate.yandex.net:443 "POST /api/v1.5/tr.json/translate HTTP/1.1" 200 79 
2019-05-12 18:21:06,390,390 DEB urllib3.connectionpool._new_conn(813) Starting new HTTPS connection (1): translate.yandex.net:443 
2019-05-12 18:21:07,074,074 DEB urllib3.connectionpool._make_request(393) https://translate.yandex.net:443 "POST /api/v1.5/tr.json/translate HTTP/1.1" 200 79 
2019-05-12 18:21:19,058,058 DEB urllib3.connectionpool._new_conn(813) Starting new HTTPS connection (1): translate.yandex.net:443 
2019-05-12 18:21:19,742,742 DEB urllib3.connectionpool._make_request(393) https://translate.yandex.net:443 "POST /api/v1.5/tr.json/translate HTTP/1.1" 200 40 
2019-05-12 18:21:19,751,751 DEB urllib3.connectionpool._new_conn(813) Starting new HTTPS connection (1): translate.yandex.net:443 
2019-05-12 18:21:20,375,375 DEB urllib3.connectionpool._make_request(393) https://translate.yandex.net:443 "POST /api/v1.5/tr.json/translate HTTP/1.1" 200 79 
2019-05-12 18:21:23,443,443 DEB urllib3.connectionpool._new_conn(813) Starting new HTTPS connection (1): translate.yandex.net:443 
2019-05-12 18:21:24,097,097 DEB urllib3.connectionpool._make_request(393) https://translate.yandex.net:443 "POST /api/v1.5/tr.json/translate HTTP/1.1" 200 41 
2019-05-12 18:21:24,108,108 DEB urllib3.connectionpool._new_conn(813) Starting new HTTPS connection (1): translate.yandex.net:443 
2019-05-12 18:21:24,858,858 DEB urllib3.connectionpool._make_request(393) https://translate.yandex.net:443 "POST /api/v1.5/tr.json/translate HTTP/1.1" 200 79 
2019-05-12 18:21:37,107,107 DEB urllib3.connectionpool._new_conn(813) Starting new HTTPS connection (1): translate.yandex.net:443 
2019-05-12 18:21:37,723,723 DEB urllib3.connectionpool._make_request(393) https://translate.yandex.net:443 "POST /api/v1.5/tr.json/translate HTTP/1.1" 200 43 
2019-05-12 18:21:37,734,734 DEB urllib3.connectionpool._new_conn(813) Starting new HTTPS connection (1): translate.yandex.net:443 
2019-05-12 18:21:38,420,420 DEB urllib3.connectionpool._make_request(393) https://translate.yandex.net:443 "POST /api/v1.5/tr.json/translate HTTP/1.1" 200 79 
2019-05-12 18:21:53,032,032 DEB urllib3.connectionpool._new_conn(813) Starting new HTTPS connection (1): translate.yandex.net:443 
2019-05-12 18:21:53,647,647 DEB urllib3.connectionpool._make_request(393) https://translate.yandex.net:443 "POST /api/v1.5/tr.json/translate HTTP/1.1" 200 48 
2019-05-12 18:21:53,663,663 DEB urllib3.connectionpool._new_conn(813) Starting new HTTPS connection (1): translate.yandex.net:443 
2019-05-12 18:21:54,787,787 DEB urllib3.connectionpool._make_request(393) https://translate.yandex.net:443 "POST /api/v1.5/tr.json/translate HTTP/1.1" 200 79 
2019-05-12 18:21:58,188,188 DEB urllib3.connectionpool._new_conn(813) Starting new HTTPS connection (1): translate.yandex.net:443 
2019-05-12 18:21:58,902,902 DEB urllib3.connectionpool._make_request(393) https://translate.yandex.net:443 "POST /api/v1.5/tr.json/translate HTTP/1.1" 200 51 
2019-05-12 18:21:58,915,915 DEB urllib3.connectionpool._new_conn(813) Starting new HTTPS connection (1): translate.yandex.net:443 
2019-05-12 18:21:59,597,597 DEB urllib3.connectionpool._make_request(393) https://translate.yandex.net:443 "POST /api/v1.5/tr.json/translate HTTP/1.1" 200 79 
2019-05-12 18:22:12,813,813 DEB urllib3.connectionpool._new_conn(813) Starting new HTTPS connection (1): translate.yandex.net:443 
2019-05-12 18:22:13,359,359 DEB urllib3.connectionpool._make_request(393) https://translate.yandex.net:443 "POST /api/v1.5/tr.json/translate HTTP/1.1" 200 48 
2019-05-12 18:22:13,369,369 DEB urllib3.connectionpool._new_conn(813) Starting new HTTPS connection (1): translate.yandex.net:443 
2019-05-12 18:22:13,926,926 DEB urllib3.connectionpool._make_request(393) https://translate.yandex.net:443 "POST /api/v1.5/tr.json/translate HTTP/1.1" 200 79 
2019-05-12 18:22:34,250,250 DEB urllib3.connectionpool._new_conn(813) Starting new HTTPS connection (1): translate.yandex.net:443 
2019-05-12 18:22:36,378,378 DEB urllib3.connectionpool._make_request(393) https://translate.yandex.net:443 "POST /api/v1.5/tr.json/translate HTTP/1.1" 200 79 
2019-05-12 18:23:00,357,357 DEB urllib3.connectionpool._new_conn(813) Starting new HTTPS connection (1): translate.yandex.net:443 
2019-05-12 18:23:01,071,071 DEB urllib3.connectionpool._make_request(393) https://translate.yandex.net:443 "POST /api/v1.5/tr.json/translate HTTP/1.1" 200 49 
2019-05-12 18:23:01,084,084 DEB urllib3.connectionpool._new_conn(813) Starting new HTTPS connection (1): translate.yandex.net:443 
2019-05-12 18:23:01,732,732 DEB urllib3.connectionpool._make_request(393) https://translate.yandex.net:443 "POST /api/v1.5/tr.json/translate HTTP/1.1" 200 79 
2019-05-12 18:23:10,797,797 DEB urllib3.connectionpool._new_conn(813) Starting new HTTPS connection (1): translate.yandex.net:443 
2019-05-12 18:23:11,626,626 DEB urllib3.connectionpool._make_request(393) https://translate.yandex.net:443 "POST /api/v1.5/tr.json/translate HTTP/1.1" 200 41 
2019-05-12 18:23:11,637,637 DEB urllib3.connectionpool._new_conn(813) Starting new HTTPS connection (1): translate.yandex.net:443 
2019-05-12 18:23:12,236,236 DEB urllib3.connectionpool._make_request(393) https://translate.yandex.net:443 "POST /api/v1.5/tr.json/translate HTTP/1.1" 200 79 
2019-05-12 18:24:13,263,263 DEB urllib3.connectionpool._new_conn(813) Starting new HTTPS connection (1): translate.yandex.net:443 
2019-05-12 18:24:13,966,966 DEB urllib3.connectionpool._make_request(393) https://translate.yandex.net:443 "POST /api/v1.5/tr.json/translate HTTP/1.1" 200 42 
2019-05-12 18:24:28,876,876 DEB urllib3.connectionpool._new_conn(813) Starting new HTTPS connection (1): translate.yandex.net:443 
2019-05-12 18:24:29,616,616 DEB urllib3.connectionpool._make_request(393) https://translate.yandex.net:443 "POST /api/v1.5/tr.json/translate HTTP/1.1" 200 42 
2019-05-12 18:25:09,565,565 DEB urllib3.connectionpool._new_conn(813) Starting new HTTPS connection (1): translate.yandex.net:443 
2019-05-12 18:25:10,150,150 DEB urllib3.connectionpool._make_request(393) https://translate.yandex.net:443 "POST /api/v1.5/tr.json/translate HTTP/1.1" 200 51 
2019-05-12 18:25:10,164,164 DEB urllib3.connectionpool._new_conn(813) Starting new HTTPS connection (1): translate.yandex.net:443 
2019-05-12 18:25:10,803,803 DEB urllib3.connectionpool._make_request(393) https://translate.yandex.net:443 "POST /api/v1.5/tr.json/translate HTTP/1.1" 200 50 
2019-05-12 19:20:51,366,366 ERR aiogram.dispatcher.dispatcher.start_polling(257) Cause exception while getting updates. 
Traceback (most recent call last):
  File "/app/venv/lib/python3.7/site-packages/aiogram/dispatcher/dispatcher.py", line 255, in start_polling
    updates = await self.bot.get_updates(limit=limit, offset=offset, timeout=timeout)
  File "/app/venv/lib/python3.7/site-packages/aiogram/bot/bot.py", line 93, in get_updates
    result = await self.request(api.Methods.GET_UPDATES, payload)
  File "/app/venv/lib/python3.7/site-packages/aiogram/bot/base.py", line 163, in request
    proxy=self.proxy, proxy_auth=self.proxy_auth, timeout=self.timeout, **kwargs)
  File "/app/venv/lib/python3.7/site-packages/aiogram/bot/api.py", line 97, in make_request
    async with session.post(url, data=req, **kwargs) as response:
  File "/app/venv/lib/python3.7/site-packages/aiohttp/client.py", line 1005, in __aenter__
    self._resp = await self._coro
  File "/app/venv/lib/python3.7/site-packages/aiohttp/client.py", line 497, in _request
    await resp.start(conn)
  File "/app/venv/lib/python3.7/site-packages/aiohttp/client_reqrep.py", line 857, in start
    self._continue = None
  File "/app/venv/lib/python3.7/site-packages/aiohttp/helpers.py", line 585, in __exit__
    raise asyncio.TimeoutError from None
concurrent.futures._base.TimeoutError
2019-05-12 19:21:28,665,665 ERR aiogram.dispatcher.dispatcher.start_polling(257) Cause exception while getting updates. 
Traceback (most recent call last):
  File "/app/venv/lib/python3.7/site-packages/aiohttp/connector.py", line 924, in _wrap_create_connection
    await self._loop.create_connection(*args, **kwargs))
  File "/usr/local/lib/python3.7/asyncio/base_events.py", line 959, in create_connection
    raise exceptions[0]
  File "/usr/local/lib/python3.7/asyncio/base_events.py", line 946, in create_connection
    await self.sock_connect(sock, address)
  File "/usr/local/lib/python3.7/asyncio/selector_events.py", line 464, in sock_connect
    return await fut
  File "/usr/local/lib/python3.7/asyncio/selector_events.py", line 469, in _sock_connect
    sock.connect(address)
OSError: [Errno 99] Address not available

The above exception was the direct cause of the following exception:

Traceback (most recent call last):
  File "/app/venv/lib/python3.7/site-packages/aiogram/bot/api.py", line 97, in make_request
    async with session.post(url, data=req, **kwargs) as response:
  File "/app/venv/lib/python3.7/site-packages/aiohttp/client.py", line 1005, in __aenter__
    self._resp = await self._coro
  File "/app/venv/lib/python3.7/site-packages/aiohttp/client.py", line 476, in _request
    timeout=real_timeout
  File "/app/venv/lib/python3.7/site-packages/aiohttp/connector.py", line 522, in connect
    proto = await self._create_connection(req, traces, timeout)
  File "/app/venv/lib/python3.7/site-packages/aiohttp/connector.py", line 854, in _create_connection
    req, traces, timeout)
  File "/app/venv/lib/python3.7/site-packages/aiohttp/connector.py", line 992, in _create_direct_connection
    raise last_exc
  File "/app/venv/lib/python3.7/site-packages/aiohttp/connector.py", line 974, in _create_direct_connection
    req=req, client_error=client_error)
  File "/app/venv/lib/python3.7/site-packages/aiohttp/connector.py", line 931, in _wrap_create_connection
    raise client_error(req.connection_key, exc) from exc
aiohttp.client_exceptions.ClientConnectorError: Cannot connect to host api.telegram.org:443 ssl:None [Address not available]

During handling of the above exception, another exception occurred:

Traceback (most recent call last):
  File "/app/venv/lib/python3.7/site-packages/aiogram/dispatcher/dispatcher.py", line 255, in start_polling
    updates = await self.bot.get_updates(limit=limit, offset=offset, timeout=timeout)
  File "/app/venv/lib/python3.7/site-packages/aiogram/bot/bot.py", line 93, in get_updates
    result = await self.request(api.Methods.GET_UPDATES, payload)
  File "/app/venv/lib/python3.7/site-packages/aiogram/bot/base.py", line 163, in request
    proxy=self.proxy, proxy_auth=self.proxy_auth, timeout=self.timeout, **kwargs)
  File "/app/venv/lib/python3.7/site-packages/aiogram/bot/api.py", line 100, in make_request
    raise exceptions.NetworkError(f"aiohttp client throws an error: {e.__class__.__name__}: {e}")
aiogram.utils.exceptions.NetworkError: Aiohttp client throws an error: ClientConnectorError: Cannot connect to host api.telegram.org:443 ssl:None [Address not available]
2019-05-12 19:21:47,233,233 ERR aiogram.dispatcher.dispatcher.start_polling(257) Cause exception while getting updates. 
Traceback (most recent call last):
  File "/app/venv/lib/python3.7/site-packages/aiohttp/connector.py", line 955, in _create_direct_connection
    traces=traces), loop=self._loop)
  File "/app/venv/lib/python3.7/site-packages/aiohttp/connector.py", line 825, in _resolve_host
    self._resolver.resolve(host, port, family=self._family)
  File "/app/venv/lib/python3.7/site-packages/aiohttp/resolver.py", line 30, in resolve
    host, port, type=socket.SOCK_STREAM, family=family)
  File "/usr/local/lib/python3.7/asyncio/base_events.py", line 789, in getaddrinfo
    None, getaddr_func, host, port, family, type, proto, flags)
  File "/usr/local/lib/python3.7/concurrent/futures/thread.py", line 57, in run
    result = self.fn(*self.args, **self.kwargs)
  File "/usr/local/lib/python3.7/socket.py", line 748, in getaddrinfo
    for res in _socket.getaddrinfo(host, port, family, type, proto, flags):
socket.gaierror: [Errno -2] Name does not resolve

The above exception was the direct cause of the following exception:

Traceback (most recent call last):
  File "/app/venv/lib/python3.7/site-packages/aiogram/bot/api.py", line 97, in make_request
    async with session.post(url, data=req, **kwargs) as response:
  File "/app/venv/lib/python3.7/site-packages/aiohttp/client.py", line 1005, in __aenter__
    self._resp = await self._coro
  File "/app/venv/lib/python3.7/site-packages/aiohttp/client.py", line 476, in _request
    timeout=real_timeout
  File "/app/venv/lib/python3.7/site-packages/aiohttp/connector.py", line 522, in connect
    proto = await self._create_connection(req, traces, timeout)
  File "/app/venv/lib/python3.7/site-packages/aiohttp/connector.py", line 854, in _create_connection
    req, traces, timeout)
  File "/app/venv/lib/python3.7/site-packages/aiohttp/connector.py", line 959, in _create_direct_connection
    raise ClientConnectorError(req.connection_key, exc) from exc
aiohttp.client_exceptions.ClientConnectorError: Cannot connect to host api.telegram.org:443 ssl:None [Name does not resolve]

During handling of the above exception, another exception occurred:

Traceback (most recent call last):
  File "/app/venv/lib/python3.7/site-packages/aiogram/dispatcher/dispatcher.py", line 255, in start_polling
    updates = await self.bot.get_updates(limit=limit, offset=offset, timeout=timeout)
  File "/app/venv/lib/python3.7/site-packages/aiogram/bot/bot.py", line 93, in get_updates
    result = await self.request(api.Methods.GET_UPDATES, payload)
  File "/app/venv/lib/python3.7/site-packages/aiogram/bot/base.py", line 163, in request
    proxy=self.proxy, proxy_auth=self.proxy_auth, timeout=self.timeout, **kwargs)
  File "/app/venv/lib/python3.7/site-packages/aiogram/bot/api.py", line 100, in make_request
    raise exceptions.NetworkError(f"aiohttp client throws an error: {e.__class__.__name__}: {e}")
aiogram.utils.exceptions.NetworkError: Aiohttp client throws an error: ClientConnectorError: Cannot connect to host api.telegram.org:443 ssl:None [Name does not resolve]
